2018-06-24 22:48:38,981 ERROR: Exception on /favicon.ico [GET] [in c:\users\user\documents\realpython\microblog\env\lib\site-packages\flask\app.py:1560]
Traceback (most recent call last):
  File "c:\users\user\documents\realpython\microblog\env\lib\site-packages\flask\app.py", line 1982, in wsgi_app
    response = self.full_dispatch_request()
  File "c:\users\user\documents\realpython\microblog\env\lib\site-packages\flask\app.py", line 1614, in full_dispatch_request
    rv = self.handle_user_exception(e)
  File "c:\users\user\documents\realpython\microblog\env\lib\site-packages\flask\app.py", line 1517, in handle_user_exception
    reraise(exc_type, exc_value, tb)
  File "c:\users\user\documents\realpython\microblog\env\lib\site-packages\flask\_compat.py", line 33, in reraise
    raise value
  File "c:\users\user\documents\realpython\microblog\env\lib\site-packages\flask\app.py", line 1610, in full_dispatch_request
    rv = self.preprocess_request()
  File "c:\users\user\documents\realpython\microblog\env\lib\site-packages\flask\app.py", line 1831, in preprocess_request
    rv = func()
  File "C:\Users\user\Documents\RealPython\microblog\app\main\routes.py", line 15, in before_request
    db.session.commit()
  File "c:\users\user\documents\realpython\microblog\env\lib\site-packages\sqlalchemy\orm\scoping.py", line 153, in do
    return getattr(self.registry(), name)(*args, **kwargs)
  File "c:\users\user\documents\realpython\microblog\env\lib\site-packages\sqlalchemy\orm\session.py", line 943, in commit
    self.transaction.commit()
  File "c:\users\user\documents\realpython\microblog\env\lib\site-packages\sqlalchemy\orm\session.py", line 467, in commit
    self._prepare_impl()
  File "c:\users\user\documents\realpython\microblog\env\lib\site-packages\sqlalchemy\orm\session.py", line 436, in _prepare_impl
    self.session.dispatch.before_commit(self.session)
  File "c:\users\user\documents\realpython\microblog\env\lib\site-packages\sqlalchemy\event\attr.py", line 246, in __call__
    fn(*args, **kw)
  File "C:\Users\user\Documents\RealPython\microblog\app\models.py", line 28, in before_commit
    'update': [obj for obj in session.dirty if isnstance(obj, cls)],
  File "C:\Users\user\Documents\RealPython\microblog\app\models.py", line 28, in <listcomp>
    'update': [obj for obj in session.dirty if isnstance(obj, cls)],
NameError: name 'isnstance' is not defined
2018-06-24 22:50:04,227 INFO: Microblog startup [in C:\Users\user\Documents\RealPython\microblog\app\__init__.py:78]
2018-06-24 23:15:54,535 INFO: Microblog startup [in C:\Users\user\Documents\RealPython\microblog\app\__init__.py:78]
2018-06-24 23:16:00,041 ERROR: Exception on /user/sussy [GET] [in c:\users\user\documents\realpython\microblog\env\lib\site-packages\flask\app.py:1560]
Traceback (most recent call last):
  File "c:\users\user\documents\realpython\microblog\env\lib\site-packages\flask\app.py", line 1982, in wsgi_app
    response = self.full_dispatch_request()
  File "c:\users\user\documents\realpython\microblog\env\lib\site-packages\flask\app.py", line 1614, in full_dispatch_request
    rv = self.handle_user_exception(e)
  File "c:\users\user\documents\realpython\microblog\env\lib\site-packages\flask\app.py", line 1517, in handle_user_exception
    reraise(exc_type, exc_value, tb)
  File "c:\users\user\documents\realpython\microblog\env\lib\site-packages\flask\_compat.py", line 33, in reraise
    raise value
  File "c:\users\user\documents\realpython\microblog\env\lib\site-packages\flask\app.py", line 1610, in full_dispatch_request
    rv = self.preprocess_request()
  File "c:\users\user\documents\realpython\microblog\env\lib\site-packages\flask\app.py", line 1831, in preprocess_request
    rv = func()
  File "C:\Users\user\Documents\RealPython\microblog\app\main\routes.py", line 16, in before_request
    g.search_form = SearchForm()
NameError: name 'SearchForm' is not defined
2018-06-24 23:20:06,426 INFO: Microblog startup [in C:\Users\user\Documents\RealPython\microblog\app\__init__.py:78]
2018-06-24 23:20:13,819 ERROR: Exception on /user/sussy [GET] [in c:\users\user\documents\realpython\microblog\env\lib\site-packages\flask\app.py:1560]
Traceback (most recent call last):
  File "c:\users\user\documents\realpython\microblog\env\lib\site-packages\flask\app.py", line 1982, in wsgi_app
    response = self.full_dispatch_request()
  File "c:\users\user\documents\realpython\microblog\env\lib\site-packages\flask\app.py", line 1614, in full_dispatch_request
    rv = self.handle_user_exception(e)
  File "c:\users\user\documents\realpython\microblog\env\lib\site-packages\flask\app.py", line 1517, in handle_user_exception
    reraise(exc_type, exc_value, tb)
  File "c:\users\user\documents\realpython\microblog\env\lib\site-packages\flask\_compat.py", line 33, in reraise
    raise value
  File "c:\users\user\documents\realpython\microblog\env\lib\site-packages\flask\app.py", line 1610, in full_dispatch_request
    rv = self.preprocess_request()
  File "c:\users\user\documents\realpython\microblog\env\lib\site-packages\flask\app.py", line 1831, in preprocess_request
    rv = func()
  File "C:\Users\user\Documents\RealPython\microblog\app\main\routes.py", line 16, in before_request
    g.search_form = SearchForm()
NameError: name 'SearchForm' is not defined
2018-06-24 23:24:39,475 INFO: Microblog startup [in C:\Users\user\Documents\RealPython\microblog\app\__init__.py:78]
2018-06-24 23:24:45,941 ERROR: Exception on /user/sussy [GET] [in c:\users\user\documents\realpython\microblog\env\lib\site-packages\flask\app.py:1560]
Traceback (most recent call last):
  File "c:\users\user\documents\realpython\microblog\env\lib\site-packages\flask\app.py", line 1982, in wsgi_app
    response = self.full_dispatch_request()
  File "c:\users\user\documents\realpython\microblog\env\lib\site-packages\flask\app.py", line 1614, in full_dispatch_request
    rv = self.handle_user_exception(e)
  File "c:\users\user\documents\realpython\microblog\env\lib\site-packages\flask\app.py", line 1517, in handle_user_exception
    reraise(exc_type, exc_value, tb)
  File "c:\users\user\documents\realpython\microblog\env\lib\site-packages\flask\_compat.py", line 33, in reraise
    raise value
  File "c:\users\user\documents\realpython\microblog\env\lib\site-packages\flask\app.py", line 1612, in full_dispatch_request
    rv = self.dispatch_request()
  File "c:\users\user\documents\realpython\microblog\env\lib\site-packages\flask\app.py", line 1598, in dispatch_request
    return self.view_functions[rule.endpoint](**req.view_args)
  File "c:\users\user\documents\realpython\microblog\env\lib\site-packages\flask_login\utils.py", line 261, in decorated_view
    return func(*args, **kwargs)
  File "C:\Users\user\Documents\RealPython\microblog\app\main\routes.py", line 69, in user
    next_url=next_url, prev_url=prev_url)
  File "c:\users\user\documents\realpython\microblog\env\lib\site-packages\flask\templating.py", line 134, in render_template
    context, ctx.app)
  File "c:\users\user\documents\realpython\microblog\env\lib\site-packages\flask\templating.py", line 116, in _render
    rv = template.render(context)
  File "c:\users\user\documents\realpython\microblog\env\lib\site-packages\jinja2\asyncsupport.py", line 76, in render
    return original_render(self, *args, **kwargs)
  File "c:\users\user\documents\realpython\microblog\env\lib\site-packages\jinja2\environment.py", line 1008, in render
    return self.environment.handle_exception(exc_info, True)
  File "c:\users\user\documents\realpython\microblog\env\lib\site-packages\jinja2\environment.py", line 780, in handle_exception
    reraise(exc_type, exc_value, tb)
  File "c:\users\user\documents\realpython\microblog\env\lib\site-packages\jinja2\_compat.py", line 37, in reraise
    raise value.with_traceback(tb)
  File "C:\Users\user\Documents\RealPython\microblog\app\templates\user.html", line 1, in top-level template code
    {% extends "base.html" %}
  File "C:\Users\user\Documents\RealPython\microblog\app\templates\base.html", line 1, in top-level template code
    {% extends 'bootstrap/base.html' %}
  File "c:\users\user\documents\realpython\microblog\env\lib\site-packages\flask_bootstrap\templates\bootstrap\base.html", line 1, in top-level template code
    {% block doc -%}
  File "c:\users\user\documents\realpython\microblog\env\lib\site-packages\flask_bootstrap\templates\bootstrap\base.html", line 4, in block "doc"
    {%- block html %}
  File "c:\users\user\documents\realpython\microblog\env\lib\site-packages\flask_bootstrap\templates\bootstrap\base.html", line 20, in block "html"
    {% block body -%}
  File "c:\users\user\documents\realpython\microblog\env\lib\site-packages\flask_bootstrap\templates\bootstrap\base.html", line 21, in block "body"
    {% block navbar %}
  File "C:\Users\user\Documents\RealPython\microblog\app\templates\base.html", line 27, in block "navbar"
    <form class="navbar-form navbar-left" method="get" action="{{ url_for('main.search') }}">
  File "c:\users\user\documents\realpython\microblog\env\lib\site-packages\flask\helpers.py", line 333, in url_for
    return appctx.app.handle_url_build_error(error, endpoint, values)
  File "c:\users\user\documents\realpython\microblog\env\lib\site-packages\flask\app.py", line 1805, in handle_url_build_error
    reraise(exc_type, exc_value, tb)
  File "c:\users\user\documents\realpython\microblog\env\lib\site-packages\flask\_compat.py", line 33, in reraise
    raise value
  File "c:\users\user\documents\realpython\microblog\env\lib\site-packages\flask\helpers.py", line 323, in url_for
    force_external=external)
  File "c:\users\user\documents\realpython\microblog\env\lib\site-packages\werkzeug\routing.py", line 1776, in build
    raise BuildError(endpoint, values, method, self)
werkzeug.routing.BuildError: Could not build url for endpoint 'main.search'. Did you mean 'main.user' instead?
2018-06-24 23:34:09,736 INFO: Microblog startup [in C:\Users\user\Documents\RealPython\microblog\app\__init__.py:78]
