2018-06-03 21:59:05,920 ERROR: Exception on /auth/reset_password_request [POST] [in c:\users\user\documents\realpython\microblog\env\lib\site-packages\flask\app.py:1560]
Traceback (most recent call last):
  File "c:\users\user\documents\realpython\microblog\env\lib\site-packages\flask\app.py", line 1982, in wsgi_app
    response = self.full_dispatch_request()
  File "c:\users\user\documents\realpython\microblog\env\lib\site-packages\flask\app.py", line 1614, in full_dispatch_request
    rv = self.handle_user_exception(e)
  File "c:\users\user\documents\realpython\microblog\env\lib\site-packages\flask\app.py", line 1517, in handle_user_exception
    reraise(exc_type, exc_value, tb)
  File "c:\users\user\documents\realpython\microblog\env\lib\site-packages\flask\_compat.py", line 33, in reraise
    raise value
  File "c:\users\user\documents\realpython\microblog\env\lib\site-packages\flask\app.py", line 1612, in full_dispatch_request
    rv = self.dispatch_request()
  File "c:\users\user\documents\realpython\microblog\env\lib\site-packages\flask\app.py", line 1598, in dispatch_request
    return self.view_functions[rule.endpoint](**req.view_args)
  File "C:\Users\user\Documents\RealPython\microblog\app\auth\routes.py", line 58, in reset_password_request
    send_password_reset_email(user)
  File "C:\Users\user\Documents\RealPython\microblog\app\auth\email.py", line 13, in send_password_reset_email
    user=user, token=token))
  File "c:\users\user\documents\realpython\microblog\env\lib\site-packages\flask\templating.py", line 134, in render_template
    context, ctx.app)
  File "c:\users\user\documents\realpython\microblog\env\lib\site-packages\flask\templating.py", line 116, in _render
    rv = template.render(context)
  File "c:\users\user\documents\realpython\microblog\env\lib\site-packages\jinja2\asyncsupport.py", line 76, in render
    return original_render(self, *args, **kwargs)
  File "c:\users\user\documents\realpython\microblog\env\lib\site-packages\jinja2\environment.py", line 1008, in render
    return self.environment.handle_exception(exc_info, True)
  File "c:\users\user\documents\realpython\microblog\env\lib\site-packages\jinja2\environment.py", line 780, in handle_exception
    reraise(exc_type, exc_value, tb)
  File "c:\users\user\documents\realpython\microblog\env\lib\site-packages\jinja2\_compat.py", line 37, in reraise
    raise value.with_traceback(tb)
  File "C:\Users\user\Documents\RealPython\microblog\app\templates\email\reset_password.html", line 10, in top-level template code
    <p>{{ url_for('reset_password', token=token, _external=True) }}</p>
  File "c:\users\user\documents\realpython\microblog\env\lib\site-packages\flask\helpers.py", line 333, in url_for
    return appctx.app.handle_url_build_error(error, endpoint, values)
  File "c:\users\user\documents\realpython\microblog\env\lib\site-packages\flask\app.py", line 1805, in handle_url_build_error
    reraise(exc_type, exc_value, tb)
  File "c:\users\user\documents\realpython\microblog\env\lib\site-packages\flask\_compat.py", line 33, in reraise
    raise value
  File "c:\users\user\documents\realpython\microblog\env\lib\site-packages\flask\helpers.py", line 323, in url_for
    force_external=external)
  File "c:\users\user\documents\realpython\microblog\env\lib\site-packages\werkzeug\routing.py", line 1776, in build
    raise BuildError(endpoint, values, method, self)
werkzeug.routing.BuildError: Could not build url for endpoint 'reset_password' with values ['token']. Did you mean 'auth.reset_password' instead?
2018-06-03 22:12:17,109 INFO: Microblog startup [in C:\Users\user\Documents\RealPython\microblog\app\__init__.py:76]
2018-06-03 22:12:31,369 ERROR: Exception on /auth/reset_password_request [POST] [in c:\users\user\documents\realpython\microblog\env\lib\site-packages\flask\app.py:1560]
Traceback (most recent call last):
  File "c:\users\user\documents\realpython\microblog\env\lib\site-packages\flask\app.py", line 1982, in wsgi_app
    response = self.full_dispatch_request()
  File "c:\users\user\documents\realpython\microblog\env\lib\site-packages\flask\app.py", line 1614, in full_dispatch_request
    rv = self.handle_user_exception(e)
  File "c:\users\user\documents\realpython\microblog\env\lib\site-packages\flask\app.py", line 1517, in handle_user_exception
    reraise(exc_type, exc_value, tb)
  File "c:\users\user\documents\realpython\microblog\env\lib\site-packages\flask\_compat.py", line 33, in reraise
    raise value
  File "c:\users\user\documents\realpython\microblog\env\lib\site-packages\flask\app.py", line 1612, in full_dispatch_request
    rv = self.dispatch_request()
  File "c:\users\user\documents\realpython\microblog\env\lib\site-packages\flask\app.py", line 1598, in dispatch_request
    return self.view_functions[rule.endpoint](**req.view_args)
  File "C:\Users\user\Documents\RealPython\microblog\app\auth\routes.py", line 60, in reset_password_request
    return redirect(url_for('login'))
  File "c:\users\user\documents\realpython\microblog\env\lib\site-packages\flask\helpers.py", line 333, in url_for
    return appctx.app.handle_url_build_error(error, endpoint, values)
  File "c:\users\user\documents\realpython\microblog\env\lib\site-packages\flask\app.py", line 1805, in handle_url_build_error
    reraise(exc_type, exc_value, tb)
  File "c:\users\user\documents\realpython\microblog\env\lib\site-packages\flask\_compat.py", line 33, in reraise
    raise value
  File "c:\users\user\documents\realpython\microblog\env\lib\site-packages\flask\helpers.py", line 323, in url_for
    force_external=external)
  File "c:\users\user\documents\realpython\microblog\env\lib\site-packages\werkzeug\routing.py", line 1776, in build
    raise BuildError(endpoint, values, method, self)
werkzeug.routing.BuildError: Could not build url for endpoint 'login'. Did you mean 'auth.login' instead?
2018-06-04 20:31:36,997 INFO: Microblog startup [in C:\Users\user\Documents\RealPython\microblog\app\__init__.py:76]
2018-06-04 23:30:06,142 INFO: Microblog startup [in C:\Users\user\Documents\RealPython\microblog\app\__init__.py:76]
2018-06-04 23:51:48,060 INFO: Microblog startup [in C:\Users\user\Documents\RealPython\microblog\app\__init__.py:76]
2018-06-21 08:56:20,527 INFO: Microblog startup [in C:\Users\user\Documents\RealPython\microblog\app\__init__.py:76]
2018-06-21 09:25:11,016 INFO: Microblog startup [in C:\Users\user\Documents\RealPython\microblog\app\__init__.py:76]
2018-06-21 14:38:27,561 INFO: Microblog startup [in C:\Users\user\Documents\RealPython\microblog\app\__init__.py:76]
2018-06-24 16:18:03,624 INFO: Microblog startup [in C:\Users\user\Documents\RealPython\microblog\app\__init__.py:76]
2018-06-24 22:48:02,445 INFO: Microblog startup [in C:\Users\user\Documents\RealPython\microblog\app\__init__.py:78]
2018-06-24 22:48:35,220 ERROR: Exception on / [GET] [in c:\users\user\documents\realpython\microblog\env\lib\site-packages\flask\app.py:1560]
Traceback (most recent call last):
  File "c:\users\user\documents\realpython\microblog\env\lib\site-packages\flask\app.py", line 1982, in wsgi_app
    response = self.full_dispatch_request()
  File "c:\users\user\documents\realpython\microblog\env\lib\site-packages\flask\app.py", line 1614, in full_dispatch_request
    rv = self.handle_user_exception(e)
  File "c:\users\user\documents\realpython\microblog\env\lib\site-packages\flask\app.py", line 1517, in handle_user_exception
    reraise(exc_type, exc_value, tb)
  File "c:\users\user\documents\realpython\microblog\env\lib\site-packages\flask\_compat.py", line 33, in reraise
    raise value
  File "c:\users\user\documents\realpython\microblog\env\lib\site-packages\flask\app.py", line 1610, in full_dispatch_request
    rv = self.preprocess_request()
  File "c:\users\user\documents\realpython\microblog\env\lib\site-packages\flask\app.py", line 1831, in preprocess_request
    rv = func()
  File "C:\Users\user\Documents\RealPython\microblog\app\main\routes.py", line 15, in before_request
    db.session.commit()
  File "c:\users\user\documents\realpython\microblog\env\lib\site-packages\sqlalchemy\orm\scoping.py", line 153, in do
    return getattr(self.registry(), name)(*args, **kwargs)
  File "c:\users\user\documents\realpython\microblog\env\lib\site-packages\sqlalchemy\orm\session.py", line 943, in commit
    self.transaction.commit()
  File "c:\users\user\documents\realpython\microblog\env\lib\site-packages\sqlalchemy\orm\session.py", line 467, in commit
    self._prepare_impl()
  File "c:\users\user\documents\realpython\microblog\env\lib\site-packages\sqlalchemy\orm\session.py", line 436, in _prepare_impl
    self.session.dispatch.before_commit(self.session)
  File "c:\users\user\documents\realpython\microblog\env\lib\site-packages\sqlalchemy\event\attr.py", line 246, in __call__
    fn(*args, **kw)
  File "C:\Users\user\Documents\RealPython\microblog\app\models.py", line 28, in before_commit
    'update': [obj for obj in session.dirty if isnstance(obj, cls)],
  File "C:\Users\user\Documents\RealPython\microblog\app\models.py", line 28, in <listcomp>
    'update': [obj for obj in session.dirty if isnstance(obj, cls)],
NameError: name 'isnstance' is not defined
